Workbook

Sheet Detalhamento RE - 1º Bimestre
A2: TOTAL | B2: Data | C2: Nº RE | D2: Nº OB | E2: DESCRIÇÃO | F2: DETALHAMENTO | G2: =SUM(G3:G27) -> 13499282 | H2: Nº GD
A3: Vlr Individual | B3: 45701 | C3: 2025RE00014 | D3: 2025OB00276 | E3: Folha de Pagamento | F3: GOVERNO DO ESTADO DO AMAPA | G3: 3384838.7
A4: Vlr Individual | B4: 45701 | C4: 2025RE00014 | D4: 2025OB00277 | E4: Folha de Pagamento | F4: BANCO DO BRASIL S/A | G4: 8576713.3
A5: Vlr Individual | B5: 45701 | C5: 2025RE00014 | D5: 2025OB00278 | E5: Folha de Pagamento | F5: ALLIANZ SEGUROS S.A | G5: 19.58
A6: Vlr Individual | B6: 45701 | C6: 2025RE00014 | D6: 2025OB00279 | E6: Folha de Pagamento | F6: ASPA MENSALIDADE | G6: 196
A7: Vlr Individual | B7: 45701 | C7: 2025RE00014 | D7: 2025OB00280 | E7: Folha de Pagamento | F7: ASPBRAS-ASSOC.DOS SERV.PUBLICOS BRASILEIROS. | G7: 93
A8: Vlr Individual | B8: 45701 | C8: 2025RE00014 | D8: 2025OB00281 | E8: Folha de Pagamento | F8: ASPEB | G8: 21000.86
A9: Vlr Individual | B9: 45701 | C9: 2025RE00014 | D9: 2025OB00283 | E9: Folha de Pagamento | F9: ASSEGUP MENS | G9: 210
A10: Vlr Individual | B10: 45701 | C10: 2025RE00014 | D10: 2025OB00284 | E10: Folha de Pagamento | F10: HSBC BAMERINDUS SEGUROS | G10: 9804.94
A11: Vlr Individual | B11: 45701 | C11: 2025RE00014 | D11: 2025OB00285 | E11: Folha de Pagamento | F11: BANCO BMG S/A | G11: 1224.56
A12: Vlr Individual | B12: 45701 | C12: 2025RE00014 | D12: 2025OB00286 | E12: Folha de Pagamento | F12: BANCO MASTER S.A | G12: 710726.23
A13: Vlr Individual | B13: 45701 | C13: 2025RE00014 | D13: 2025OB00288 | E13: Folha de Pagamento | F13: BANCO OLE BONSUCESSO CONSIGNADO S/A | G13: 50314.08
A14: Vlr Individual | B14: 45701 | C14: 2025RE00014 | D14: 2025OB00289 | E14: Folha de Pagamento | F14: BANCO CRUZEIRO DO SUL S/A | G14: 327.45
... A20: Vlr Individual | B20: 45701 | C20: 2025RE00014 | D20: 2025OB00297 | E20: Folha de Pagamento | F20: AGENCIA DE FOMENTO DO AMAPA S/A AFAP | G20: 2267.14
A21: Vlr Individual | B21: 45701 | C21: 2025RE00014 | D21: 2025OB00298 | E21: Folha de Pagamento | F21: R.S.P.P.ASS.PREV.PRIVADA | G21: 111.18 | H21: 2025GD00002
A22: Vlr Individual | B22: 45701 | C22: 2025RE00014 | D22: 2025OB00299 | E22: Folha de Pagamento | F22: SINSEPEAP-SIND.SERV.PUB.EDUC.AP | G22: 184954.83
A23: Vlr Individual | B23: 45701 | C23: 2025RE00014 | D23: 2025OB00300 | E23: Folha de Pagamento | F23: SINDICATO DOS EMPREG. EM EMP. DE PROC. DE DADOS... | G23: 13.09
A24: Vlr Individual | B24: 45701 | C24: 2025RE00014 | D24: 2025OB00301 | E24: Folha de Pagamento | F24: SIND. DOS SERVIDORES GRUPO GESTÃO ADM DO EST. D... | G24: 478.49
A25: Vlr Individual | B25: 45701 | C25: 2025RE00014 | D25: 2025OB00302 | E25: Folha de Pagamento | F25: SUL AMERICA SEGUROS DE VIDA E PREVIDENCIA S/A. | G25: 320.23
A26: Vlr Individual | B26: 45701 | C26: 2025RE00014 | D26: 2025OB00303 | E26: Folha de Pagamento | F26: UNIODONTO | G26: 87239
A27: Vlr Individual | B27: 45701 | C27: 2025RE00014 | D27: 2025OB00304 | E27: Folha de Pagamento | F27: PDT CONTRIBUIÇÃO | G27: 470.99
A29: TOTAL | B29: Data | C29: Nº RE | D29: Nº OB | E29: DESCRIÇÃO | F29: DETALHAMENTO | G29: =SUM(G30:G33) -> 3493620 | H29: Nº GD
A30: Vlr Individual | B30: 45701 | C30: 2025RE00015 | D30: 2025OB00282 | E30: Folha de Pagamento | F30: ASS.ASSIST.FUNC.PUBLICO MENSALIDADE | G30: 229
A31: Vlr Individual | B31: 45701 | C31: 2025RE00015 | D31: 2025OB00287 | E31: Folha de Pagamento | F31: BANCO MASTER S.A | G31: 327604.14
A32: Vlr Individual | B32: 45701 | C32: 2025RE00015 | D32: 2025OB00294 | E32: Folha de Pagamento | F32: BANCO SANTANDER BANESPA S.A | G32: 3139248.7
A33: Vlr Individual | B33: 45701 | C33: 2025RE00015 | D33: 2025OB00296 | E33: Folha de Pagamento | F33: AGENCIA DE FOMENTO DO AMAPA S/A AFAP | G33: 26538.12
A35: TOTAL | B35: Data | C35: Nº RE | D35: Nº OB | E35: DESCRIÇÃO | F35: DETALHAMENTO | G35: =SUM(G36:G43) -> 18292925 | H35: Nº GD
A36: Vlr Individual | B36: 45702 | C36: 2025RE00028 | D36: 2025OB00588 | E36: Folha de Pagamento | F36: GOVERNO DO ESTADO DO AMAPA | G36: 7619659.9
A37: Vlr Individual | B37: 45702 | C37: 2025RE00028 | D37: 2025OB00589 | E37: Folha de Pagamento | F37: SECRETARIA DA RECEITA FEDERAL DO BRASIL (MINISTÉRIO DA FAZENDA) | G37: 20585.63
A38: Vlr Individual | B38: 45702 | C38: 2025RE00028 | D38: 2025OB00590 | E38: Folha de Pagamento | F38: GOVERNO DO ESTADO DO AMAPA | G38: 3742.61
A39: Vlr Individual | B39: 45702 | C39: 2025RE00028 | D39: 2025OB00591 | E39: Folha de Pagamento | F39: AMAPÁ PREVIDÊNCIA | G39: 2779824.2
A40: Vlr Individual | B40: 45702 | C40: 2025RE00028 | D40: 2025OB00592 | E40: Folha de Pagamento | F40: AMAPÁ PREVIDÊNCIA | G40: 5031863.6
A41: Vlr Individual | B41: 45702 | C41: 2025RE00028 | D41: 2025OB00593 | E41: Folha de Pagamento | F41: SECRETARIA DA RECEITA FEDERAL DO BRASIL (MINISTÉRIO DA FAZENDA) | G41: 52204.18
A42: Vlr Individual | B42: 45702 | C42: 2025RE00028 | D42: 2025OB00594 | E42: Folha de Pagamento | F42: SECRETARIA DA RECEITA FEDERAL DO BRASIL (MINISTÉRIO DA FAZENDA) | G42: 5220.42
A43: Vlr Individual | B43: 45702 | C43: 2025RE00028 | D43: 2025OB00595 | E43: Folha de Pagamento | F43: AMAPÁ PREVIDÊNCIA | G43: 2779824.2
A45: TOTAL | B45: Data | C45: Nº RE | D45: Nº OB | E45: DESCRIÇÃO | F45: DETALHAMENTO | G45: =SUM(G46:G49) -> 5528457.6 | H45: Nº GD
A46: Vlr Individual | B46: 45705 | C46: 2025RE00031 | D46: 2025OB00597 | E46: Folha de Pagamento | F46: GOVERNO DO ESTADO DO AMAPA | G46: 496593.96
A47: Vlr Individual | B47: 45705 | C47: 2025RE00031 | D47: 2025OB00598 | E47: Folha de Pagamento | F47: AMAPÁ PREVIDÊNCIA | G47: 597619.08
A48: Vlr Individual | B48: 45705 | C48: 2025RE00031 | D48: 2025OB00599 | E48: Folha de Pagamento | F48: AMAPÁ PREVIDÊNCIA | G48: 2646092.9
A49: Vlr Individual | B49: 45705 | C49: 2025RE00031 | D49: 2025OB00600 | E49: Folha de Pagamento | F49: AMAPÁ PREVIDÊNCIA | G49: 1788151.6
...

Sheet Extrato 01-2025
A1: Extrato Conta Corrente
A2: Agencia | C2: =SUBTOTAL(9,C4:C99) -> 1.4322821e+08
A3: Data | B3: Historico | C3: Valor R$ | D3: Inf. | E3: Detalhamento Hist.
A4: 10/01/2025 | B4: IPVA | C4: 33292.32 | D4: C | E4: Transferência Constitucional - FUNDEB
A5: 10/01/2025 | B5: ITR | C5: 801.48 | D5: C | E5: Transferência Constitucional - FUNDEB
A6: 10/01/2025 | B6: RECEBIMENTO DE ICMS | C6: 1473123.3 | D6: C | E6: Transferência Constitucional - FUNDEB
A7: 10/01/2025 | B7: FPE/FPM | C7: 974097.66 | D7: C | E7: Transferência Constitucional - FUNDEB
A8: 10/01/2025 | B8: FPE/FPM | C8: 2264490.5 | D8: C | E8: Transferência Constitucional - FUNDEB
A9: 10/01/2025 | B9: FPE/FPM | C9: 26660819 | D9: C | E9: Transferência Constitucional - FUNDEB
A10: 10/01/2025 | B10: FPE/FPM | C10: 11459.95 | D10: C | E10: Transferência Constitucional - FUNDEB
A11: 10/01/2025 | B11: IPI/EXPORTACAO | C11: 21145.69 | D11: C | E11: IPI/EXPORTACAO - Cota Débito
A12: 10/01/2025 | B12: IPI/EXPORTACAO | C12: 12267.68 | D12: C | E12: Transferência Constitucional - FUNDEB
A13: 10/01/2025 | B13: COTA DAF-DEBITO | C13: 21145.69 | D13: D | E13: IPI/EXPORTACAO - Cota Débito
A14: 10/01/2025 | B14: BB-APLIC C.PRZ-APL.AUT | C14: 31430352 | D14: D | E14: Aplicação Financeira
A15: 13/01/2025 | B15: TED Transf.Eletr.Disponiv | C15: 1664.17 | D15: D | E15: Férias
... A93: 31/01/2025 | B93: BB-APLIC C.PRZ-APL.AUT | C93: 5462074.1 | D93: D | E93: Aplicação Financeira

Sheet Extrato 02-2025
A1: Extrato Conta Corrente
A2: Agencia | C2: =SUBTOTAL(9,C4:C80) -> 1.8573717e+08
A3: Data | B3: Historico | C3: Valor R$ | D3: Inf. | E3: Detalhamento Hist. | F3: RE
A4: 06/02/2025 | B4: Tar Lib/Ant Float Pg Div | C4: 1771 | D4: D | E4: Tarifa Bancária
A5: 06/02/2025 | B5: Resgate Automático | C5: 1771 | D5: C | E5: Resgate Automático
A6: 10/02/2025 | B6: ITCMD | C6: 52425.39 | D6: C | E6: Transferência Constitucional - FUNDEB
A7: 10/02/2025 | B7: RECEBIMENTO DE ICMS | C7: 783899.29 | D7: C | E7: Transferência Constitucional - FUNDEB
A8: 10/02/2025 | B8: ITR | C8: 1070.01 | D8: C | E8: Transferência Constitucional - FUNDEB
A9: 10/02/2025 | B9: FPE/FPM | C9: 2254096.5 | D9: C | E9: Transferência Constitucional - FUNDEB
A10: 10/02/2025 | B10: FPE/FPM | C10: 5240110.9 | D10: C | E10: Transferência Constitucional - FUNDEB
A11: 10/02/2025 | B11: FPE/FPM | C11: 59156698 | D11: C | E11: Transferência Constitucional - FUNDEB
A12: 10/02/2025 | B12: FPE/FPM | C12: 26518.78 | D12: C | E12: Transferência Constitucional - FUNDEB
A13: 10/02/2025 | B13: IPI/EXPORTACAO | C13: 24106.25 | D13: C | E13: IPI/EXPORTACAO - Cota Débito
A14: 10/02/2025 | B14: IPI/EXPORTACAO | C14: 13985.23 | D14: C | E14: Transferência Constitucional - FUNDEB
A15: 10/02/2025 | B15: COTA DAF-DEBITO | C15: 24106.25 | D15: D | E15: IPI/EXPORTACAO - Cota Débito
... A17: 13/02/2025 | B17: ORDEM BANC CANCELADA | C17: 111.18 | D17: C | E17: ORDEM BANC CANCELADA
A18: 13/02/2025 | B18: Emissão Ordem Bancária | C18: 13499282 | D18: D | E18: Folha de Pagamento | F18: 2025RE00014
A19: 13/02/2025 | B19: Emissão Ordem Bancária | C19: 3493620 | D19: D | E19: Folha de Pagamento | F19: 2025RE00015
A20: 13/02/2025 | B20: Tar Lib/Ant Float Pg Div | C20: 17.2 | D20: D | E20: Tarifa Bancária
A21: 13/02/2025 | B21: Tar Lib/Ant Float Pg Div | C21: 20.24 | D21: D | E21: Tarifa Bancária
A22: 13/02/2025 | B22: Resgate Automático | C22: 16992828 | D22: C | E22: Resgate Automático
A23: 14/02/2025 | B23: Pagamentos Diversos | C23: 10029.56 | D23: D | E23: Pagamentos Diversos
A24: 14/02/2025 | B24: Emissão Ordem Bancária | C24: 18292925 | D24: D | E24: Folha de Pagamento | F24: 2025RE00028
A25: 14/02/2025 | B25: Resgate Automático | C25: 18302954 | D25: C | E25: Resgate Automático
A26: 17/02/2025 | B26: ITCMD | C26: 52425.39 | D26: C | E26: Transferência Constitucional - FUNDEB
A27: 17/02/2025 | B27: RECEBIMENTO DE ICMS | C27: 783899.29 | D27: C | E27: Transferência Constitucional - FUNDEB
A28: 17/02/2025 | B28: Emissão Ordem Bancária | C28: 5528457.6 | D28: D | E28: Folha de Pagamento | F28: 2025RE00031
A29: 17/02/2025 | B29: Tar Lib/Ant Float Pg Div | C29: 5.09 | D29: D | E29: Tarifa Bancária
A30: 17/02/2025 | B30: Tar Lib/Ant Float Pg Div | C30: 10.02 | D30: D | E30: Tarifa Bancária
A31: 17/02/2025 | B31: Tar Lib/Ant Float Pg Div | C31: 6.73 | D31: D | E31: Tarifa Bancária
A32: 17/02/2025 | B32: Resgate Automático | C32: 4692154.7 | D32: C | E32: Resgate Automático
A33: 20/02/2025 | B33: ITR | C33: 73.24 | D33: C | E33: Transferência Constitucional - FUNDEB
A34: 20/02/2025 | B34: IPI/EXPORTACAO | C34: 10960.52 | D34: C | E34: IPI/EXPORTACAO - Cota Débito
A35: 20/02/2025 | B35: IPI/EXPORTACAO | C35: 6358.75 | D35: C | E35: Transferência Constitucional - FUNDEB
A36: 20/02/2025 | B36: FPE/FPM | C36: 225249.85 | D36: C | E36: Transferência Constitucional - FUNDEB
A37: 20/02/2025 | B37: FPE/FPM | C37: 523639.75 | D37: C | E37: Transferência Constitucional - FUNDEB
A38: 20/02/2025 | B38: FPE/FPM | C38: 5873079.8 | D38: C | E38: Transferência Constitucional - FUNDEB
A39: 20/02/2025 | B39: FPE/FPM | C39: 2649.98 | D39: C | E39: Transferência Constitucional - FUNDEB
A40: 20/02/2025 | B40: COTA DAF-DEBITO | C40: 10960.52 | D40: D | E40: IPI/EXPORTACAO - Cota Débito
A41: 20/02/2025 | B41: BB-APLIC C.PRZ-APL.AUT | C41: 6631051.4 | D41: D | E41: Aplicação Financeira
...

Sheet REF - 1º Bimestre
D2: =SUBTOTAL(9,D4:D64) -> 90916811
A3: PD | B3: OB | C3: Credor | D3: 2 - Fevereiro | E3: Mês de Ocorrência | F3: RE | G3: GD
A4: 2025PD00318 | B4: 2025OB00292 | C4: PF0000023 - FOLHA DE PAGAMENTO | D4: 84 | E4: Extrato de Fevereiro | F4: 2025RE00014
A5: 2025PD00748 | B5: 2025OB00806 | C5: PF0000023 - FOLHA DE PAGAMENTO | D5: 333.78 | E5: Extrato de Janeiro
A6: 2025PD00693 | B6: 2025OB00805 | C6: PF0000023 - FOLHA DE PAGAMENTO | D6: 333.78 | E6: Extrato de Janeiro
A7: 2025PD00749 | B7: 2025OB00807 | C7: PF0000023 - FOLHA DE PAGAMENTO | D7: 21025.56 | E7: Extrato de Janeiro
A8: 2025PD00646 | B8: 2025OB00802 | C8: PF0000023 - FOLHA DE PAGAMENTO | D8: 265580.97 | E8: Férias
A9: 2025PD00616 | B9: 2025OB00597 | C9: PF0000023 - FOLHA DE PAGAMENTO | D9: 496593.96 | E9: Extrato de Fevereiro | F9: 2025RE00031
A10: 2025PD00650 | B10: 2025OB00808 | C10: PF0000023 - FOLHA DE PAGAMENTO | D10: 10505937 | E10: Férias
A11: 2025PD00277 | B11: 2025OB00276 | C11: PF0000023 - FOLHA DE PAGAMENTO | D11: 3384838.7 | E11: Extrato de Fevereiro | F11: 2025RE00014
A12: 2025PD00292 | B12: 2025OB00277 | C12: PF0000023 - FOLHA DE PAGAMENTO | D12: 8576713.3 | E12: Extrato de Fevereiro | F12: 2025RE00014
A13: 2025PD00302 | B13: 2025OB00278 | C13: PF0000023 - FOLHA DE PAGAMENTO | D13: 19.58 | E13: Extrato de Fevereiro | F13: 2025RE00014
A14: 2025PD00305 | B14: 2025OB00279 | C14: PF0000023 - FOLHA DE PAGAMENTO | D14: 196 | E14: Extrato de Fevereiro | F14: 2025RE00014
A15: 2025PD00306 | B15: 2025OB00280 | C15: PF0000023 - FOLHA DE PAGAMENTO | D15: 93 | E15: Extrato de Fevereiro | F15: 2025RE00014
A16: 2025PD00307 | B16: 2025OB00281 | C16: PF0000023 - FOLHA DE PAGAMENTO | D16: 21000.86 | E16: Extrato de Fevereiro | F16: 2025RE00014
A17: 2025PD00308 | B17: 2025OB00282 | C17: PF0000023 - FOLHA DE PAGAMENTO | D17: 229 | E17: Extrato de Fevereiro | F17: 2025RE00015
A18: 2025PD00309 | B18: 2025OB00283 | C18: PF0000023 - FOLHA DE PAGAMENTO | D18: 210 | E18: Extrato de Fevereiro | F18: 2025RE00014
A19: 2025PD00310 | B19: 2025OB00284 | C19: PF0000023 - FOLHA DE PAGAMENTO | D19: 9804.94 | E19: Extrato de Fevereiro | F19: 2025RE00014
A20: 2025PD00311 | B20: 2025OB00285 | C20: PF0000023 - FOLHA DE PAGAMENTO | D20: 1224.56 | E20: Extrato de Fevereiro | F20: 2025RE00014
A21: 2025PD00312 | B21: 2025OB00286 | C21: PF0000023 - FOLHA DE PAGAMENTO | D21: 710726.23 | E21: Extrato de Fevereiro | F21: 2025RE00014
A22: 2025PD00313 | B22: 2025OB00287 | C22: PF0000023 - FOLHA DE PAGAMENTO | D22: 327604.14 | E22: Extrato de Fevereiro | F22: 2025RE00015
... A31: 2025PD00323 | B31: 2025OB00297 | C31: PF0000023 - FOLHA DE PAGAMENTO | D31: 2267.14 | E31: Extrato de Fevereiro | F31: 2025RE00014
A32: 2025PD00324 | B32: 2025OB00298 | C32: PF0000023 - FOLHA DE PAGAMENTO | D32: 0 | E32: Extrato de Fevereiro | F32: 2025RE00014 | G32: 2025GD00002
A33: 2025PD00325 | B33: 2025OB00299 | C33: PF0000023 - FOLHA DE PAGAMENTO | D33: 184954.83 | E33: Extrato de Fevereiro | F33: 2025RE00014
A34: 2025PD00326 | B34: 2025OB00300 | C34: PF0000023 - FOLHA DE PAGAMENTO | D34: 13.09 | E34: Extrato de Fevereiro | F34: 2025RE00014
A35: 2025PD00327 | B35: 2025OB00301 | C35: PF0000023 - FOLHA DE PAGAMENTO | D35: 478.49 | E35: Extrato de Fevereiro | F35: 2025RE00014
A36: 2025PD00328 | B36: 2025OB00302 | C36: PF0000023 - FOLHA DE PAGAMENTO | D36: 320.23 | E36: Extrato de Fevereiro | F36: 2025RE00014
A37: 2025PD00329 | B37: 2025OB00303 | C37: PF0000023 - FOLHA DE PAGAMENTO | D37: 87239 | E37: Extrato de Fevereiro | F37: 2025RE00014
A38: 2025PD00330 | B38: 2025OB00304 | C38: PF0000023 - FOLHA DE PAGAMENTO | D38: 470.99 | E38: Extrato de Fevereiro | F38: 2025RE00014
A39: 2025PD00660 | B39: 2025OB00803 | C39: PF0000023 - FOLHA DE PAGAMENTO | D39: 36251.68 | E39: Salário de 01/2024
A40: 2025PD00824 | B40: 2025OB00727 | C40: PF0000023 - FOLHA DE PAGAMENTO | D40: 333.78 | E40: Extrato de Fevereiro | F40: 2025RE00042
A41: 2025PD00662 | B41: 2025OB00804 | C41: PF0000023 - FOLHA DE PAGAMENTO | D41: 856836.89 | E41: Salário de 01/2024
A42: 2025PD00587 | B42: 2025OB00588 | C42: PF0000023 - FOLHA DE PAGAMENTO | D42: 7619659.9 | E42: Extrato de Fevereiro | F42: 2025RE00028
A43: 2025PD00588 | B43: 2025OB00589 | C43: PF0000023 - FOLHA DE PAGAMENTO | D43: 20585.63 | E43: Extrato de Fevereiro | F43: 2025RE00028
A44: 2025PD00589 | B44: 2025OB00590 | C44: PF0000023 - FOLHA DE PAGAMENTO | D44: 3742.61 | E44: Extrato de Fevereiro | F44: 2025RE00028
A45: 2025PD00592 | B45: 2025OB00591 | C45: PF0000023 - FOLHA DE PAGAMENTO | D45: 2779824.2 | E45: Extrato de Fevereiro | F45: 2025RE00028
A46: 2025PD00593 | B46: 2025OB00592 | C46: PF0000023 - FOLHA DE PAGAMENTO | D46: 5031863.6 | E46: Extrato de Fevereiro | F46: 2025RE00028
A47: 2025PD00667 | B47: 2025OB00811 | C47: PF0000023 - FOLHA DE PAGAMENTO | D47: 9102905.2 | E47: Salário de 01/2024
A48: 2025PD00590 | B48: 2025OB00593 | C48: 00394460005887 - SECRETARIA DA RECEITA FEDERAL DO BRASIL (MINISTÉRIO DA FAZENDA) | D48: 52204.18 | E48: Extrato de Fevereiro | F48: 2025RE00028
A49: 2025PD00591 | B49: 2025OB00594 | C49: 00394460005887 - SECRETARIA DA RECEITA FEDERAL DO BRASIL (MINISTÉRIO DA FAZENDA) | D49: 5220.42 | E49: Extrato de Fevereiro | F49: 2025RE00028
...

Sheet Saldos - 01-2025
B2: CONCILIAÇÃO BANCÁRIA DO EXTRATO BANCÁRIO - JANEIRO DE 2025
B4: 1. Ingressos | E4: Valores do Mês | F4: Acumulado
B5: 1.0 IPI - EXP | E5: 59369.1 | F5: =E5 -> 59369.1
B6: 1.1 VAAR | E6: 1477881.8 | F6: =E6 -> 1477881.8
B7: 1.2 FPE/FPM | E7: 74152666 | F7: =E7 -> 74152666
B8: 1.3 ICMS | E8: 17391685 | F8: =E8 -> 17391685
B9: 1.4 IPVA | E9: 34348.74 | F9: =E9 -> 34348.74
B10: 1.5 ITCMD | E10: 20855.66 | F10: =E10 -> 20855.66
B11: 1.6 ITR | E11: 1452.04 | F11: =E11 -> 1452.04
B12: 1.7 ORDEM BANC CANCELADA | E12: 0 | F12: =E12 -> 0
B13: 1.8 RESGATE | E13: 50089950 | F13: =E13 -> 50089950
B14: 2 Total das Entradas | E14: =SUM(E5:E13) -> 1.4322821e+08 | F14: =SUM(F5:F13) -> 1.4322821e+08
B15: 3.0 (-) IPI/Cota DAF Deb | E15: -37571.82 | F15: =E15 -> -37571.82
B16: 3.1 (-) Ordem Bancária Cancelada | E16: 0 | F16: =E16 -> 0
B17: 3.2 (-) Resgastes efetuados | E17: -50089950 | F17: =E17 -> -50089950
B18: 3.3 (-) Ajuste VAAR - FNDE | E18: -164645.69 | F18: =E18 -> -164645.69
B19: 3. Total Disponibizado( 1 - 3.0- 3.1 - 3.2 -3.3 - 3.4 ) | E19: =SUM(E14:E18) -> 92936040 | F19: =SUM(F14:F18) -> 92936040
B21: 4. Saídas | E21: Valores do Mês | F21: Acumulado
B22: 4.1 Cota DAF Deb | E22: 37571.82 | F22: =E22 -> 37571.82
B23: 4.2 O.B.s Canceladas | F23: =E23 -> 0
B24: 4.3.1 Folha de Pagamento - Encargos | E24: 79099.41 | F24: =E24 -> 79099.41
B25: 4.3.2 Folha de Pagamento - Folha 01/2025 | E25: 34311367 | F25: =E25 -> 34311367
B26: 4.3.3 Folha de Pagamento - Férias | E26: 15697876 | F26: =E26 -> 15697876
B27: 4.3.4 Ajuste VAAR | E27: 164645.69 | F27: =E27 -> 164645.69
B28: 4.3.5 GRU-GUIA RECOLHIM. UNIAO | E28: 667.56 | F28: =E28 -> 667.56
B29: 4.4 Tarifa bancária | E29: 5628.71 | F29: =E29 -> 5628.71
B30: 4.5 Aplicações Efetuadas | E30: 92931352 | F30: =E30 -> 92931352
B31: 5. Total Geral das Saídas | E31: =SUM(E22:E30) -> 1.4322821e+08 | F31: =SUM(F22:F30) -> 1.4322821e+08
B32: 6.1 (-) Cota DAF Deb | E32: =-E22 -> -37571.82 | F32: =E32 -> -37571.82
B33: 6.2 (-) Aplicações Efetuadas | E33: =-E30 -> -92931352 | F33: =E33 -> -92931352
B34: 6.3 ( - ) O.B.s Canceladas | E34: =-E23 -> 0 | F34: =E34 -> 0
B35: 6.4 Tarifa bancária | E35: =-E29 -> -5628.71 | F35: =E35 -> -5628.71
B36: 6.5 (-) Pagamento Folha não regularizado
B37: 6.6 (+) Regularização de Folha e não Pago | E37: 13294.61 | F37: =E37 -> 13294.61
B38: 6.7 (-) Ajuste VAAR - FNDE | F38: =-F27 -> -164645.69
B39: Despesa Total do Mês ( confere com o relatório de execução financeira do SEAFI ) | E39: =SUM(E31:E38) -> 50266950 | F39: =SUM(F31:F38) -> 50102305
B41: CONTA INVESTIMENTO
B42: saldo Inicial | E42: 15778860
B43: Aplicação | E43: 92931352
B44: Resgaste | E44: 50089950
...

Sheet Cálculo Conciliação 1º Bimestre
C3: Saldo dos Pagamentos do SEAFI | D3: =SUM(D5:D9) -> 1.4604409e+08 | E3: =D3-'[1]Demonst Exec Financ Conciliado'!$J$89 -> 11470.64
C5: Extrato de Janeiro | D5: =[2]Janeiro!G1 -> 58285284
C6: SEAFI a maior | D6: 8949.47 | G6: =D6+D5 -> 58294233
C7: Extrato de Fevereiro | D7: =[2]Fevereiro!G1 -> 88938686
C8: SEAFI a menor ( regularizado em março ) | D8: -1194723.6 | E8: pago em março
C9: SEAFI a maior | D9: 5894.85 | G9: =SUM(D7:D9) -> 87749857
C11: COMPOSIÇÃO DE SALDO DO FUNDEB
C12: 1º BIMESTRE DE 2025
C14: Dsiponibilidade Financeira em 31/12/2024 | D14: 15778860 | I14: 6.1469606e+08
C15: ( + ) Ingressos = Transferências Constitucionais - janeiro-2024 | D15: 92936040
C16: ( + ) Ingressos = Transferências Constitucionais - fevereiro-2024 | D16: 1.115289e+08 | I16: =D16+D15 -> 2.0446494e+08
C17: ( + ) Ingressos = Rendimentos do FUNDEB - 1º Bimestre | D17: 901662.73 | I17: =D17+I16 -> 2.053666e+08
C18: ( - ) Pagamentos Efetuados = Relatório de Execução Financeira | D18: -90916811
C19: ( - ) Pagto Tarifa Bancária não regularizada no SEAFI | D19: ='Saldos - 02-2025'!F37 -> -7459.99
C20: ( + ) Regularização Folha - não Pago | D20: =D36 -> 13294.61 | I20: =D19+D21+D22+D23 -> -34193739
C21: ( - ) Pagamento de Folha não regularizada no mês | D21: -34175582
C22: ( - ) Pagamentos Diversos - Folha | D22: -10029.56
C23: ( - ) GRU Paga e Não Regularizada | D23: -667.56
C27: ( = ) Saldo do SIOPE | D27: =SUM(D14:D26) -> 96048208
C29: Dsiponibilidade Financeira em 28/02/2025 | D29: ='Saldos - 02-2025'!E50 -> 96048208
C31: Diferença a identificar | D31: =D27-D29 -> 0.010000035
C34: Regularização - Janeiro/2024 | D34: =D35+13294.61 -> 34324662
C35: Pagto - Janeiro/2024 | D35: 34311367
D36: =D34-D35 -> 13294.61
C38: Regularização - Fevereiro/2024
C39: Pagto - Fevereiro/2024
D40: =D38-D39 -> 0
C42: Regularização não Pago | D42: =D36+D40 -> 13294.61

Sheet Saldos - 02-2025
B2: CONCILIAÇÃO BANCÁRIA DO EXTRATO BANCÁRIO - FEVEREIRO DE 2025
B4: 1. Ingressos | E4: Valores do Mês | F4: Acumulado
B5: 1.0 IPI - EXP | E5: 67206.18 | F5: =E5+'Saldos - 01-2025'!F5 -> 126575.28
B6: 1.1 VAAR | F6: =E6+'Saldos - 01-2025'!F6 -> 1477881.8
B7: 1.2 FPE/FPM | E7: 97471124 | F7: =E7+'Saldos - 01-2025'!F7 -> 1.7162379e+08
B8: 1.3 ICMS | E8: 12205256 | F8: =E8+'Saldos - 01-2025'!F8 -> 29596941
B9: 1.4 IPVA | E9: 1721670.2 | F9: =E9+'Saldos - 01-2025'!F9 -> 1756018.9
B10: 1.5 ITCMD | E10: 104850.78 | F10: =E10+'Saldos - 01-2025'!F10 -> 125706.44
B11: 1.6 ITR | E11: 1324 | F11: =E11+'Saldos - 01-2025'!F11 -> 2776.04
B12: 1.7 ORDEM BANC CANCELADA | E12: 111.18 | F12: =E12+'Saldos - 01-2025'!F12 -> 111.18
B13: 1.8 RESGATE | E13: 74165624 | F13: =E13+'Saldos - 01-2025'!F13 -> 1.2425557e+08
B14: 2 Total das Entradas | E14: =SUM(E5:E13) -> 1.8573717e+08 | F14: =SUM(F5:F13) -> 3.2896537e+08
B15: 3.0 (-) IPI/Cota DAF Deb | E15: -42531.54 | F15: =E15+'Saldos - 01-2025'!F15 -> -80103.36
B16: 3.1 (-) Ordem Bancária Cancelada | E16: -111.18 | F16: =E16+'Saldos - 01-2025'!F16 -> -111.18
B17: 3.2 (-) Resgastes efetuados | E17: -74165624 | F17: =E17+'Saldos - 01-2025'!F17 -> -1.2425557e+08
B18: 3.3 (-) Ajuste VAAR - FNDE | E18: 0 | F18: =E18+'Saldos - 01-2025'!F18 -> -164645.69
B19: 3. Total Disponibizado( 1 - 3.0- 3.1 - 3.2 -3.3 - 3.4 ) | E19: =SUM(E14:E18) -> 1.115289e+08 | F19: =SUM(F14:F18) -> 2.0446494e+08
B21: 4. Saídas | E21: Valores do Mês | F21: Acumulado
B22: 4.1 Cota DAF Deb | E22: 42531.54 | F22: =E22+'Saldos - 01-2025'!F22 -> 80103.36
B23: 4.2 O.B.s Canceladas | F23: =E23+'Saldos - 01-2025'!F23 -> 0
B24: 4.3.1 Folha de Pagamento - Encargos e Identificados por RE | E24: 40814618 | F24: =E24+'Saldos - 01-2025'!F24 -> 40893717
B25: 4.3.2 Folha de Pagamento - Folha 01/2025 | E25: 0 | F25: =E25+'Saldos - 01-2025'!F25 -> 34311367
B26: 4.3.3 Folha de Pagamento - Folha 02/2025 | E26: 34175582 | F26: =E26 -> 34175582
B27: 4.3.4 Folha de Pagamento - Férias | E27: 0 | F27: =E27+'Saldos - 01-2025'!F26 -> 15697876
B28: 4.3.5 Ajuste VAAR | E28: 0 | F28: =E28+'Saldos - 01-2025'!F27 -> 164645.69
B29: 4.3.6 GRU-GUIA RECOLHIM. UNIAO | E29: 667.56 | F29: =E29+'Saldos - 01-2025'!F28 -> 1335.12
B30: 4.3.7 Pagamentos Diversos - Folha | E30: 10029.56 | F30: =E30 -> 10029.56
B31: 4.4 Tarifa bancária | E31: 1831.28 | F31: =E31+'Saldos - 01-2025'!F29 -> 7459.99
B32: 4.5 (-) Aplicações Efetuadas | E32: 1.1069191e+08 | F32: =E32+'Saldos - 01-2025'!F30 -> 2.0362326e+08
B33: 5. Total Geral das Saídas | E33: =SUM(E22:E32) -> 1.8573717e+08 | F33: =SUM(F22:F32) -> 3.2896537e+08
B34: 6.1 (-) Cota DAF Deb | E34: =-E22 -> -42531.54 | F34: =E34+'Saldos - 01-2025'!F32 -> -80103.36
B35: 6.2 (-) Aplicações Efetuadas | E35: =-E32 -> -1.1069191e+08 | F35: =E35+'Saldos - 01-2025'!F33 -> -2.0362326e+08
B36: 6.3 (-) O.B.s Canceladas | E36: -111.18 | F36: =E36+'Saldos - 01-2025'!F34 -> -111.18
B37: 6.4 (-) Tarifa bancária | E37: =-E31 -> -1831.28 | F37: =E37+'Saldos - 01-2025'!F35 -> -7459.99
B38: 6.5 (-) Pagamento Folha não regularizado | E38: =-E26 -> -34175582 | F38: =E38 -> -34175582
B39: 6.6 (-) Ajustes VAAR | E39: 0 | F39: =E39+'Saldos - 01-2025'!F38 -> -164645.69
B40: 6.7 (-) Pagamentos Diversos | E40: =-E30 -> -10029.56 | F40: =E40 -> -10029.56
B41: 6.7 (+) Regularização de Folha e não Pago | E41: 0 | F41: =(E41+'Saldos - 01-2025'!F37) -> 13294.61
B42: 6.8 (-) GRU Paga e Não Regularizada | E42: -667.56 | F42: =E42 -> -667.56
B43: Despesa Total do Mês ( confere com o relatório de execução financeira do SEAFI ) | E43: =SUM(E33:E42) -> 40814507 | F43: =SUM(F33:F42) -> 90916811
...

Sheet REF - Março
D2: =SUBTOTAL(9,D4:D69) -> 34317010
A3: PD | B3: OB | C3: Credor | D3: 3 - Março | E3: Mês de Ocorrência | F3: RE | G3: GD
A4: 2025PD01304 | B4: 2025OB03433 | C4: PF0000023 - FOLHA DE PAGAMENTO | D4: 333.78 | E4: Fevereiro
A5: 2025PD01305 | B5: 2025OB03434 | C5: PF0000023 - FOLHA DE PAGAMENTO | D5: 333.78 | E5: Fevereiro
A6: 2025PD01183 | B6: 2025OB01123 | C6: PF0000023 - FOLHA DE PAGAMENTO | D6: 333.78 | F6: 2025RE00070
A7: 2025PD02593 | B7: 2025OB03435 | C7: PF0000023 - FOLHA DE PAGAMENTO | D7: 333.78 | E7: Março
A8: 2025PD02594 | B8: 2025OB03436 | C8: PF0000023 - FOLHA DE PAGAMENTO | D8: 333.78 | E8: Março
A9: 2025PD03570 | B9: 2025OB03605 | C9: PF0000023 - FOLHA DE PAGAMENTO | D9: 36928.09 | E9: Folha - 02/2025
A10: 2025PD03571 | B10: 2025OB03606 | C10: PF0000023 - FOLHA DE PAGAMENTO | D10: 861371.64 | E10: Folha - 02/2025
A11: 2025PD01035 | B11: 2025OB01014 | C11: PF0000023 - FOLHA DE PAGAMENTO | D11: 19.58 | F11: 2025RE00061
A12: 2025PD01036 | B12: 2025OB01015 | C12: PF0000023 - FOLHA DE PAGAMENTO | D12: 176 | F12: 2025RE00061
A13: 2025PD01038 | B13: 2025OB01016 | C13: PF0000023 - FOLHA DE PAGAMENTO | D13: 93 | F13: 2025RE00062
A14: 2025PD01039 | B14: 2025OB01017 | C14: PF0000023 - FOLHA DE PAGAMENTO | D14: 20848.87 | F14: 2025RE00061
A15: 2025PD01040 | B15: 2025OB01018 | C15: PF0000023 - FOLHA DE PAGAMENTO | D15: 229 | F15: 2025RE00061
A16: 2025PD01041 | B16: 2025OB01019 | C16: PF0000023 - FOLHA DE PAGAMENTO | D16: 195 | F16: 2025RE00061
A17: 2025PD01042 | B17: 2025OB01020 | C17: PF0000023 - FOLHA DE PAGAMENTO | D17: 9804.94 | F17: 2025RE00061
A18: 2025PD01043 | B18: 2025OB01021 | C18: PF0000023 - FOLHA DE PAGAMENTO | D18: 2050.26 | F18: 2025RE00061
A19: 2025PD01044 | B19: 2025OB01022 | C19: PF0000023 - FOLHA DE PAGAMENTO | D19: 726074.89 | F19: 2025RE00061
A20: 2025PD01045 | B20: 2025OB01023 | C20: PF0000023 - FOLHA DE PAGAMENTO | D20: 348118.74 | F20: 2025RE00061
A21: 2025PD01046 | B21: 2025OB01024 | C21: PF0000023 - FOLHA DE PAGAMENTO | D21: 48628.7 | F21: 2025RE00061
A22: 2025PD01048 | B22: 2025OB01025 | C22: PF0000023 - FOLHA DE PAGAMENTO | D22: 327.45 | F22: 2025RE00061
... A42: 2025PD01382 | B42: 2025OB01432 | C42: PF0000023 - FOLHA DE PAGAMENTO | D42: 19479.1 | F42: 2025RE00077
A43: 2025PD03557 | B43: 2025OB03505 | C43: PF0000023 - FOLHA DE PAGAMENTO | D43: 16792661 | E43: Folha - 02/2025
A44: 2025PD03253 | B44: 2025OB03265 | C44: PF0000023 - FOLHA DE PAGAMENTO | D44: 333.78 | E44: Março
A45: 2025PD03480 | B45: 2025OB03437 | C45: PF0000023 - FOLHA DE PAGAMENTO | D45: 37214.98 | E45: Folha - 03/2025
A46: 2025PD03481 | B46: 2025OB03438 | C46: PF0000023 - FOLHA DE PAGAMENTO | D46: 854057.43 | E46: Folha - 03/2025
A47: 2025PD03482 | B47: 2025OB03448 | C47: PF0000023 - FOLHA DE PAGAMENTO | D47: 9119273.7 | E47: Folha - 03/2025
A48: 2025PD03560 | B48: 2025OB03508 | C48: PF0000023 - FOLHA DE PAGAMENTO | D48: 13457.07 | E48: Folha - 02/2025
A49: 2025PD03485 | B49: 2025OB03451 | C49: PF0000023 - FOLHA DE PAGAMENTO | D49: 180 | E49: Folha - 03/2025
A50: 2025PD03562 | B50: 2025OB03510 | C50: PF0000023 - FOLHA DE PAGAMENTO | D50: 1991924.1 | E50: Folha - 02/2025
A51: 2025PD03486 | B51: 2025OB03452 | C51: PF0000023 - FOLHA DE PAGAMENTO | D51: 2579108.5 | E51: Folha - 03/2025
A52: 2025PD01206 | B52: 2025OB01124 | C52: 03281445000185 - AMAPÁ PREVIDÊNCIA | D52: 2761697.8 | F52: 2025RE00070
A53: 2025PD01207 | B53: 2025OB01125 | C53: 03281445000185 - AMAPÁ PREVIDÊNCIA | D53: 2705928.8 | F53: 2025RE00070
A54: 2025PD03564 | B54: 2025OB03512 | C54: PF0000023 - FOLHA DE PAGAMENTO | D54: 2232230 | E54: Folha - 02/2025
A55: 2025PD03487 | B55: 2025OB03453 | C55: PF0000023 - FOLHA DE PAGAMENTO | D55: 2206423.2 | E55: Folha - 03/2025
A56: 2025PD03558 | B56: 2025OB03506 | C56: PF0000023 - FOLHA DE PAGAMENTO | D56: 4685774.1 | E56: Folha - 02/2025
A57: 2025PD03483 | B57: 2025OB03449 | C57: PF0000023 - FOLHA DE PAGAMENTO | D57: 4652945 | E57: Folha - 03/2025
A58: 2025PD01208 | B58: 2025OB01126 | C58: 03281445000185 - AMAPÁ PREVIDÊNCIA | D58: 602213.03 | F58: 2025RE00070
A59: 2025PD01130 | B59: 2025OB01121 | C59: PF0000023 - FOLHA DE PAGAMENTO | D59: 2761697.8 | F59: 2025RE00070
A60: 2025PD01131 | B60: 2025OB01122 | C60: PF0000023 - FOLHA DE PAGAMENTO | D60: 5110039.1 | F60: 2025RE00070
...

Sheet Detalhamento RE - 2º Bimestre
A2: TOTAL | B2: Data | C2: Nº RE | D2: Nº OB | E2: DESCRIÇÃO | F2: DETALHAMENTO | G2: =SUM(G3:G27) -> 4987406.9 | H2: Nº GD
A3: Vlr Individual | B3: 45723 | C3: 2025RE00061 | D3: 2025OB01014 | E3: Folha de Pagamento | F3: ALLIANZ SEGUROS S.A | G3: 19.58
A4: Vlr Individual | B4: 45723 | C4: 2025RE00061 | D4: 2025OB01015 | E4: Folha de Pagamento | F4: ASPA MENSALIDADE | G4: 176
A5: Vlr Individual | B5: 45723 | C5: 2025RE00061 | D5: 2025OB01017 | E5: Folha de Pagamento | F5: ASPEB | G5: 20848.87
A6: Vlr Individual | B6: 45723 | C6: 2025RE00061 | D6: 2025OB01018 | E6: Folha de Pagamento | F6: ASS.ASSIST.FUNC.PUBLICO MENSALIDADE | G6: 229
A7: Vlr Individual | B7: 45723 | C7: 2025RE00061 | D7: 2025OB01019 | E7: Folha de Pagamento | F7: ASSEGUP MENS | G7: 195
A8: Vlr Individual | B8: 45723 | C8: 2025RE00061 | D8: 2025OB01020 | E8: Folha de Pagamento | F8: HSBC BAMERINDUS SEGUROS | G8: 9804.94
A9: Vlr Individual | B9: 45723 | C9: 2025RE00061 | D9: 2025OB01021 | E9: Folha de Pagamento | F9: BANCO BMG S/A | G9: 2050.26
A10: Vlr Individual | B10: 45723 | C10: 2025RE00061 | D10: 2025OB01022 | E10: Folha de Pagamento | F10: BANCO MASTER S.A | G10: 726074.89
A11: Vlr Individual | B11: 45723 | C11: 2025RE00061 | D11: 2025OB01023 | E11: Folha de Pagamento | F11: BANCO MASTER S.A | G11: 348118.74
A12: Vlr Individual | B12: 45723 | C12: 2025RE00061 | D12: 2025OB01024 | E12: Folha de Pagamento | F12: BANCO OLE BONSUCESSO CONSIGNADO S/A | G12: 48628.7
A13: Vlr Individual | B13: 45723 | C13: 2025RE00061 | D13: 2025OB01025 | E13: Folha de Pagamento | F13: BANCO CRUZEIRO DO SUL S/A | G13: 327.45
A14: Vlr Individual | B14: 45723 | C14: 2025RE00061 | D14: 2025OB01026 | E14: Folha de Pagamento | F14: BANCO INDUSTRIAL DO BRASIL S/A - BI | G14: 393757.5
... A22: Vlr Individual | B22: 45723 | C22: 2025RE00061 | D22: 2025OB01036 | E22: Folha de Pagamento | F22: AGENCIA DE FOMENTO DO AMAPA S/A AFAP | G22: 1882.48
A23: Vlr Individual | B23: 45723 | C23: 2025RE00061 | D23: 2025OB01037 | E23: Folha de Pagamento | F23: R.S.P.P.ASS.PREV.PRIVADA | G23: 111.18 | H23: 2025GD00009
A24: Vlr Individual | B24: 45723 | C24: 2025RE00061 | D24: 2025OB01038 | E24: Folha de Pagamento | F24: SINSEPEAP-SIND.SERV.PUB.EDUC.AP | G24: 183951.72
A25: Vlr Individual | B25: 45723 | C25: 2025RE00061 | D25: 2025OB01039 | E25: Folha de Pagamento | F25: SINDICATO DOS EMPREG. EM EMP. DE PROC. DE DADOS... | G25: 13.09
A26: Vlr Individual | B26: 45723 | C26: 2025RE00061 | D26: 2025OB01041 | E26: Folha de Pagamento | F26: SUL AMERICA SEGUROS DE VIDA E PREVIDENCIA S/A. | G26: 320.23
A27: Vlr Individual | B27: 45723 | C27: 2025RE00061 | D27: 2025OB01043 | E27: Folha de Pagamento | F27: PDT CONTRIBUIÇÃO | G27: 470.99
A29: TOTAL | B29: Data | C29: Nº RE | D29: Nº OB | E29: DESCRIÇÃO | F29: DETALHAMENTO | G29: =SUM(G30:G34) -> 12139973 | H29: Nº GD
A30: Vlr Individual | B30: 45723 | C30: 2025RE00062 | D30: 2025OB01016 | E30: Folha de Pagamento | F30: ASPBRAS-ASSOC.DOS SERV.PUBLICOS BRASILEIROS. | G30: 93
A31: Vlr Individual | B31: 45723 | C31: 2025RE00062 | D31: 2025OB01029 | E31: Folha de Pagamento | F31: BANCO DO BRASIL S/A | G31: 8643454.1
A32: Vlr Individual | B32: 45723 | C32: 2025RE00062 | D32: 2025OB01031 | E32: Folha de Pagamento | F32: GOVERNO DO ESTADO DO AMAPA | G32: 3409140
A33: Vlr Individual | B33: 45723 | C33: 2025RE00062 | D33: 2025OB01040 | E33: Folha de Pagamento | F33: SIND. DOS SERVIDORES GRUPO GESTÃO ADM DO EST. DO AP - SINSGAAP | G33: 478.49
A34: Vlr Individual | B34: 45723 | C34: 2025RE00062 | D34: 2025OB01042 | E34: Folha de Pagamento | F34: UNIODONTO | G34: 86807
A36: TOTAL | B36: Data | C36: Nº RE | D36: Nº OB | E36: DESCRIÇÃO | F36: DETALHAMENTO | G36: =SUM(G37:G45) -> 23448006 | H36: Nº GD
A37: Vlr Individual | B37: 45726 | C37: 2025RE00070 | D37: 2025OB01119 | E37: Folha de Pagamento | F37: GOVERNO DO ESTADO DO AMAPA | G37: 7701836.7
A38: Vlr Individual | B38: 45726 | C38: 2025RE00070 | D38: 2025OB01120 | E38: Folha de Pagamento | F38: GOVERNO DO ESTADO DO AMAPA | G38: 2361.69
A39: Vlr Individual | B39: 45726 | C39: 2025RE00070 | D39: 2025OB01121 | E39: Folha de Pagamento | F39: AMAPÁ PREVIDÊNCIA | G39: 2761697.8
A40: Vlr Individual | B40: 45726 | C40: 2025RE00070 | D40: 2025OB01122 | E40: Folha de Pagamento | F40: AMAPÁ PREVIDÊNCIA | G40: 5110039.1
A41: Vlr Individual | B41: 45726 | C41: 2025RE00070 | D41: 2025OB01123 | E41: Folha de Pagamento | F41: GOVERNO DO ESTADO DO AMAPA | G41: 333.78
A42: Vlr Individual | B42: 45726 | C42: 2025RE00070 | D42: 2025OB01124 | E42: Folha de Pagamento | F42: AMAPÁ PREVIDÊNCIA | G42: 2761697.8
A43: Vlr Individual | B43: 45726 | C43: 2025RE00070 | D43: 2025OB01125 | E43: Folha de Pagamento | F43: AMAPÁ PREVIDÊNCIA | G43: 2705928.8
A44: Vlr Individual | B44: 45726 | C44: 2025RE00070 | D44: 2025OB01126 | E44: Folha de Pagamento | F44: AMAPÁ PREVIDÊNCIA | G44: 602213.03
A45: Vlr Individual | B45: 45726 | C45: 2025RE00070 | D45: 2025OB01127 | E45: Folha de Pagamento | F45: AMAPÁ PREVIDÊNCIA | G45: 1801897.3
A47: TOTAL | B47: Data | C47: Nº RE | D47: Nº OB | E47: DESCRIÇÃO | F47: DETALHAMENTO | G47: =SUM(G48:G50) -> 73816.17 | H47: Nº GD
A48: Vlr Individual | B48: 45730 | C48: 2025RE00077 | D48: 2025OB01432 | E48: Folha de Pagamento | F48: GOVERNO DO ESTADO DO AMAPA | G48: 19479.1
A49: Vlr Individual | B49: 45730 | C49: 2025RE00077 | D49: 2025OB01433 | E49: Folha de Pagamento | F49: AMAPÁ PREVIDÊNCIA | G49: 49397.34
A50: Vlr Individual | B50: 45730 | C50: 2025RE00077 | D50: 2025OB01434 | E50: Folha de Pagamento | F50: AMAPÁ PREVIDÊNCIA | G50: 4939.73
A52: TOTAL | B52: Data | C52: Nº RE | D52: Nº OB | E52: DESCRIÇÃO | F52: DETALHAMENTO | G52: =SUM(G53:G57) -> 320307.99 | H52: Nº GD
...

Sheet Extrato 03-2025
A1: Extrato Conta Corrente
A2: Agencia | C2: =SUBTOTAL(9,C3:C78) -> 1.3530326e+08
A3: Data | B3: Historico | C3: Valor R$ | D3: Inf. | E3: Detalhamento Hist. | F3: Detalhamentos
A4: 07/03/2025 | B4: ORDEM BANC CANCELADA | C4: 111.18 | D4: C
A5: 07/03/2025 | B5: Emissão Ordem Bancária | C5: 4987406.9 | D5: D | E5: Folha de Pagamento | F5: 2025RE00061
A6: 07/03/2025 | B6: Emissão Ordem Bancária | C6: 12139973 | D6: D | E6: Folha de Pagamento | F6: 2025RE00062
A7: 07/03/2025 | B7: Resgate Automático | C7: 17127268 | D7: C | E7: Resgate Automático
A8: 10/03/2025 | B8: ITR | C8: 480.27 | D8: C | E8: Transferência Constitucional - FUNDEB
A9: 10/03/2025 | B9: FPE/FPM | C9: 970971.61 | D9: C | E9: Transferência Constitucional - FUNDEB
A10: 10/03/2025 | B10: FPE/FPM | C10: 2257223.4 | D10: C | E10: Transferência Constitucional - FUNDEB
A11: 10/03/2025 | B11: FPE/FPM | C11: 25914802 | D11: C | E11: Transferência Constitucional - FUNDEB
A12: 10/03/2025 | B12: FPE/FPM | C12: 11423.16 | D12: C | E12: Transferência Constitucional - FUNDEB
A13: 10/03/2025 | B13: IPI/EXPORTACAO | C13: 26118.74 | D13: C | E13: IPI/EXPORTACAO - Cota Débito
A14: 10/03/2025 | B14: IPI/EXPORTACAO | C14: 15152.8 | D14: C | E14: Transferência Constitucional - FUNDEB
A15: 10/03/2025 | B15: COTA DAF-DEBITO | C15: 26118.74 | D15: D | E15: IPI/EXPORTACAO - Cota Débito
A16: 10/03/2025 | B16: Emissão Ordem Bancária | C16: 23448006 | D16: D | E16: Folha de Pagamento | F16: 2025RE00070
A17: 10/03/2025 | B17: BB-APLIC C.PRZ-APL.AUT | C17: 5722047.8 | D17: D | E17: Aplicação Financeira
A18: 13/03/2025 | B18: Folha de Pagamento | C18: 2548.93 | D18: D
A19: 13/03/2025 | B19: Resgate Automático | C19: 2548.93 | D19: C | E19: Resgate Automático
A20: 14/03/2025 | B20: Emissão Ordem Bancária | C20: 73816.17 | D20: D | E20: Folha de Pagamento | F20: 2025RE00077
A21: 14/03/2025 | B21: Resgate Automático | C21: 73816.17 | D21: C | E21: Resgate Automático
A22: 18/03/2025 | B22: IPVA | C22: 513105.27 | D22: C | E22: Transferência Constitucional - FUNDEB
A23: 18/03/2025 | B23: IPVA | C23: 347235.51 | D23: C | E23: Transferência Constitucional - FUNDEB
A24: 18/03/2025 | B24: RECEBIMENTO DE ICMS | C24: 2663359.6 | D24: C | E24: Transferência Constitucional - FUNDEB
A25: 18/03/2025 | B25: RECEBIMENTO DE ICMS | C25: 1605970.9 | D25: C | E25: Transferência Constitucional - FUNDEB
A26: 18/03/2025 | B26: BB-APLIC C.PRZ-APL.AUT | C26: 5129671.2 | D26: D | E26: Aplicação Financeira
A27: 20/03/2025 | B27: ITR | C27: 49 | D27: C | E27: Transferência Constitucional - FUNDEB
A28: 20/03/2025 | B28: FPE/FPM | C28: 208080.3 | D28: C | E28: Transferência Constitucional - FUNDEB
A29: 20/03/2025 | B29: FPE/FPM | C29: 483725.54 | D29: C | E29: Transferência Constitucional - FUNDEB
A30: 20/03/2025 | B30: FPE/FPM | C30: 5579351.7 | D30: C | E30: Transferência Constitucional - FUNDEB
A31: 20/03/2025 | B31: FPE/FPM | C31: 2447.97 | D31: C | E31: Transferência Constitucional - FUNDEB
A32: 20/03/2025 | B32: IPI/EXPORTACAO | C32: 11434.81 | D32: C | E32: IPI/EXPORTACAO - Cota Débito
... A34: 20/03/2025 | B34: COTA DAF-DEBITO | C34: 11434.81 | D34: D | E34: IPI/EXPORTACAO - Cota Débito
A35: 20/03/2025 | B35: Pagto via Auto-Atend.BB | C35: 333.78 | D35: D | E35: GRU-GUIA RECOLHIM. UNIAO | F35: 2025OB03435
A36: 20/03/2025 | B36: Pagto via Auto-Atend.BB | C36: 333.78 | D36: D | E36: GRU-GUIA RECOLHIM. UNIAO | F36: 2025OB03436
A37: 20/03/2025 | B37: BB-APLIC C.PRZ-APL.AUT | C37: 6279620.8 | D37: D | E37: Aplicação Financeira
A38: 24/03/2025 | B38: IPVA | C38: 1176171.2 | D38: C | E38: Transferência Constitucional - FUNDEB
A39: 24/03/2025 | B39: RECEBIMENTO DE ICMS | C39: 7632815.7 | D39: C | E39: Transferência Constitucional - FUNDEB
A40: 24/03/2025 | B40: BB-APLIC C.PRZ-APL.AUT | C40: 8808986.9 | D40: D | E40: Aplicação Financeira
A41: 26/03/2025 | B41: Pagto via Auto-Atend.BB | C41: 333.78 | D41: D | E41: GRU-GUIA RECOLHIM. UNIAO | F41: 2025OB03607 | G41: Regularizado em Abril
...

Sheet Saldos - 03-2025
B2: CONCILIAÇÃO BANCÁRIA DO EXTRATO BANCÁRIO - MARÇO DE 2025
B4: 1. Ingressos | E4: Valores do Mês | F4: Acumulado
B5: 1.0 IPI - EXP | E5: 73189.58 | F5: =E5+'Saldos - 02-2025'!F5 -> 199764.86
B6: 1.1 VAAR | E6: 0 | F6: =E6+'Saldos - 02-2025'!F6 -> 1477881.8
B7: 1.2 FPE/FPM | E7: 64600083 | F7: =E7+'Saldos - 02-2025'!F7 -> 2.3622387e+08
B8: 1.3 ICMS | E8: 14909966 | F8: =E8+'Saldos - 02-2025'!F8 -> 44506908
B9: 1.4 IPVA | E9: 4219366.5 | F9: =E9+'Saldos - 02-2025'!F9 -> 5975385.4
B10: 1.5 ITCMD | E10: 0 | F10: =E10+'Saldos - 02-2025'!F10 -> 125706.44
B11: 1.6 ITR | E11: 640.43 | F11: =E11+'Saldos - 02-2025'!F11 -> 3416.47
B12: 1.7 ORDEM BANC CANCELADA | E12: 111.18 | F12: =E12+'Saldos - 02-2025'!F12 -> 222.36
B13: 1.8 RESGATE | E13: 51499900 | F13: =E13+'Saldos - 02-2025'!F13 -> 1.7575547e+08
B14: 2 Total das Entradas | E14: =SUM(E5:E13) -> 1.3530326e+08 | F14: =SUM(F5:F13) -> 4.6426863e+08
B15: 3.0 (-) IPI/Cota DAF Deb | E15: -46318.11 | F15: =E15+'Saldos - 02-2025'!F15 -> -126421.47
B16: 3.1 (-) Ordem Bancária Cancelada | E16: =-E12 -> -111.18 | F16: =E16+'Saldos - 02-2025'!F16 -> -222.36
B17: 3.2 (-) Resgastes efetuados | E17: =-E13 -> -51499900 | F17: =E17+'Saldos - 02-2025'!F17 -> -1.7575547e+08
B18: 3.3 (-) Ajuste VAAR - FNDE | F18: =E18+'Saldos - 02-2025'!F18 -> -164645.69
B19: 3. Total Disponibizado( 1 - 3.0- 3.1 - 3.2 -3.3 - 3.4 ) | E19: =SUM(E14:E18) -> 83756928 | F19: =SUM(F14:F18) -> 2.8822187e+08
B21: 4. Saídas | E21: Valores do Mês | F21: Acumulado
B22: 4.1 Cota DAF Deb | E22: 46318.11 | F22: =E22+'Saldos - 02-2025'!F22 -> 126421.47
B23: 4.2 O.B.s Canceladas | E23: 0 | F23: =E23+'Saldos - 02-2025'!F23 -> 0
B24: 4.3.1 Folha de Pagamento - Encargos e Identificados por RE | E24: 40969510 | F24: =E24+'Saldos - 02-2025'!F24 -> 81863227
B25: 4.3.2 Folha de Pagamento - Folha 01/2025 | E25: 0 | F25: =E25+'Saldos - 02-2025'!F25 -> 34311367
B26: 4.3.3 Folha de Pagamento - Folha 02/2025 | E26: 0 | F26: =E26+'Saldos - 02-2025'!F26 -> 34175582
B27: 4.3.4 Folha de Pagamento - Folha 03/2025 | E27: 33980888 | F27: =E27 -> 33980888
B28: 4.3.5 Folha de Pagamento - Férias | E28: 0 | F28: =E28+'Saldos - 02-2025'!F27 -> 15697876
B29: 4.3.6 Ajuste VAAR | F29: =E29+'Saldos - 02-2025'!F28 -> 164645.69
B30: 4.3.7 GRU-GUIA RECOLHIM. UNIAO | E30: 1668.9 | F30: =E30+'Saldos - 02-2025'!F29 -> 3004.02
B31: 4.3.8 Pagamentos Diversos - Folha | E31: 10029.56 | F31: =E31+'Saldos - 02-2025'!F30 -> 20059.12
B32: 4.4 Tarifa bancária | E32: 30.52 | F32: =E32+'Saldos - 02-2025'!F31 -> 7490.51
B33: 4.5 Aplicações Efetuadas | E33: 60294813 | F33: =E33+'Saldos - 02-2025'!F32 -> 2.6391807e+08
B34: 5. Total Geral das Saídas | E34: =SUM(E22:E33) -> 1.3530326e+08 | F34: =SUM(F22:F33) -> 4.6426863e+08 | H34: =E34-E14 -> 0
B35: 6.1 (-) Cota DAF Deb | E35: =-E22 -> -46318.11 | F35: =E35+'Saldos - 02-2025'!F34 -> -126421.47
B36: 6.2 (-) Aplicações Efetuadas | E36: =-E33 -> -60294813 | F36: =E36+'Saldos - 02-2025'!F35 -> -2.6391807e+08
B37: 6.3 (-) O.B.s Canceladas | F37: =E37+'Saldos - 02-2025'!F36 -> -111.18
B38: 6.4 (-) Tarifa bancária | E38: =-E32 -> -30.52 | F38: =E38+'Saldos - 02-2025'!F37 -> -7490.51
B39: 6.5 (-) Pagamento Folha não regularizado | F39: =E39+'Saldos - 02-2025'!F38 -> -34175582
B40: 6.6 (-) Ajustes VAAR | F40: =E40+'Saldos - 02-2025'!F39 -> -164645.69
B41: 6.7 (-) Pagamentos Diversos | E41: -10029.56 | F41: =E41+'Saldos - 02-2025'!F40 -> -20059.12
B42: 6.7 (+) Regularização de Folha e não Pago | E42: 34210176 | F42: =E42+'Saldos - 02-2025'!F41 -> 34223471
B43: 6.8 (-) GRU Paga e Não Regularizada | F43: =E43+'Saldos - 02-2025'!F42 -> -667.56
...

Sheet REF - Abril
D2: =SUBTOTAL(9,D3:D54) -> 35678021
A3: PD | B3: OB | C3: Credor | D3: 4 - Abril | E3: Mês de Ocorrência | F3: RE | G3: GD
A4: 2025PD03583 | B4: 2025OB03607 | C4: PF0000023 - FOLHA DE PAGAMENTO | D4: 333.78 | E4: Extrato de Março | F4: Março
A5: 2025PD03584 | B5: 2025OB03608 | C5: PF0000023 - FOLHA DE PAGAMENTO | D5: 333.78 | E5: Extrato de Abril | F5: Abril
A6: 2025PD03673 | B6: 2025OB03568 | C6: PF0000023 - FOLHA DE PAGAMENTO | D6: 19.58 | E6: Extrato de Abril | F6: 2025RE00144
A7: 2025PD03677 | B7: 2025OB03569 | C7: PF0000023 - FOLHA DE PAGAMENTO | D7: 176 | E7: Extrato de Abril | F7: 2025RE00144
A8: 2025PD03678 | B8: 2025OB03570 | C8: PF0000023 - FOLHA DE PAGAMENTO | D8: 88 | E8: Extrato de Abril | F8: 2025RE00144
A9: 2025PD03679 | B9: 2025OB03571 | C9: PF0000023 - FOLHA DE PAGAMENTO | D9: 20498.9 | E9: Extrato de Abril | F9: 2025RE00144
A10: 2025PD03680 | B10: 2025OB03572 | C10: PF0000023 - FOLHA DE PAGAMENTO | D10: 229 | E10: Extrato de Abril | F10: 2025RE00144
A11: 2025PD03681 | B11: 2025OB03573 | C11: PF0000023 - FOLHA DE PAGAMENTO | D11: 180 | E11: Extrato de Abril | F11: 2025RE00144
A12: 2025PD03682 | B12: 2025OB03574 | C12: PF0000023 - FOLHA DE PAGAMENTO | D12: 9698.14 | E12: Extrato de Abril | F12: 2025RE00144
A13: 2025PD03683 | B13: 2025OB03575 | C13: PF0000023 - FOLHA DE PAGAMENTO | D13: 1763.47 | E13: Extrato de Abril | F13: 2025RE00144
A14: 2025PD03693 | B14: 2025OB03576 | C14: PF0000023 - FOLHA DE PAGAMENTO | D14: 46332.19 | E14: Extrato de Abril | F14: 2025RE00144
A15: 2025PD03694 | B15: 2025OB03577 | C15: PF0000023 - FOLHA DE PAGAMENTO | D15: 302.39 | E15: Extrato de Abril | F15: 2025RE00144
... A38: 2025PD03838 | B38: 2025OB04001 | C38: PF0000023 - FOLHA DE PAGAMENTO | D38: 5079916.6 | E38: Extrato de Abril | F38: 2025RE00159
A39: 2025PD08332 | B39: 2025OB08957 | C39: PF0000023 - FOLHA DE PAGAMENTO | D39: 18873.57 | E39: Extrato de Abril | F39: Abril | I39: =D39+D43+D44 -> 71493.75
A40: 2025PD10009 | B40: 2025OB09825 | C40: PF0000023 - FOLHA DE PAGAMENTO | D40: 37344.32 | E40: Extrato de Abril | F40: Folha 04-2025
A41: 2025PD10020 | B41: 2025OB09826 | C41: PF0000023 - FOLHA DE PAGAMENTO | D41: 884675.77 | E41: Extrato de Abril | F41: Folha 04-2025
A42: 2025PD10024 | B42: 2025OB09829 | C42: PF0000023 - FOLHA DE PAGAMENTO | D42: 9644740.5 | E42: Extrato de Abril | F42: Folha 04-2025
A43: 2025PD08333 | B43: 2025OB08958 | C43: 00394460005887 - SECRETARIA DA RECEITA FEDERAL DO BRASIL (MINISTÉRIO DA FAZENDA) | D43: 47836.53 | E43: Extrato de Abril | F43: Abril
A44: 2025PD08334 | B44: 2025OB08959 | C44: 00394460005887 - SECRETARIA DA RECEITA FEDERAL DO BRASIL (MINISTÉRIO DA FAZENDA) | D44: 4783.65 | E44: Extrato de Abril | F44: Abril
A45: 2025PD10031 | B45: 2025OB09832 | C45: PF0000023 - FOLHA DE PAGAMENTO | D45: 1526.03 | E45: Extrato de Abril | F45: Folha 04-2025
A46: 2025PD10034 | B46: 2025OB09833 | C46: PF0000023 - FOLHA DE PAGAMENTO | D46: 2428284.1 | E46: Extrato de Abril | F46: Folha 04-2025
A47: 2025PD03845 | B47: 2025OB04002 | C47: 03281445000185 - AMAPÁ PREVIDÊNCIA | D47: 2706694.4 | E47: Extrato de Abril | F47: 2025RE00159
A48: 2025PD03848 | B48: 2025OB04003 | C48: 03281445000185 - AMAPÁ PREVIDÊNCIA | D48: 2701804.6 | E48: Extrato de Abril | F48: 2025RE00159
A49: 2025PD10038 | B49: 2025OB09834 | C49: PF0000023 - FOLHA DE PAGAMENTO | D49: 2192761.7 | E49: Extrato de Abril | F49: Folha 04-2025
A50: 2025PD10026 | B50: 2025OB09830 | C50: PF0000023 - FOLHA DE PAGAMENTO | D50: 4896872.9 | E50: Extrato de Abril | F50: Folha 04-2025
A51: 2025PD03849 | B51: 2025OB04004 | C51: 03281445000185 - AMAPÁ PREVIDÊNCIA | D51: 595700.62 | E51: Extrato de Abril | F51: 2025RE00159
... A54: 2025PD10040 | B54: 2025OB09835 | C54: PF0000023 - FOLHA DE PAGAMENTO | D54: 939755 | E54: Extrato de Abril | F54: Folha 04-2025
D55: 75751224

Sheet Extrato 04-2025
A1: Extrato Conta Corrente
A2: Agencia | C2: =SUBTOTAL(9,C3:C69) -> 1.57665e+08
A3: Data | B3: Historico | C3: Valor R$ | D3: Inf. | E3: Detalhamento Hist. | F3: Detalhamentos
A4: 03/04/2025 | B4: IPVA | C4: 250252.14 | D4: C | E4: Transferência Constitucional - FUNDEB
A5: 03/04/2025 | B5: Emissão Ordem Bancária | C5: 460041.44 | D5: D | E5: Folha de Pagamento | F5: 2025RE00144
A6: 03/04/2025 | B6: Resgate Automático | C6: 209789.3 | D6: C | E6: Resgate Automático
A7: 04/04/2025 | B7: ORDEM BANC CANCELADA | C7: 103.93 | D7: C
A8: 04/04/2025 | B8: Emissão Ordem Bancária | C8: 31900062 | D8: D | E8: Folha de Pagamento | F8: 2025RE00159
A9: 04/04/2025 | B9: Emissão Ordem Bancária | C9: 7641042 | D9: D | E9: Folha de Pagamento | F9: 2025RE00160
A10: 04/04/2025 | B10: Resgate Automático | C10: 39541000 | D10: C | E10: Resgate Automático
A11: 07/04/2025 | B11: RECEBIMENTO DE ICMS | C11: 764797.82 | D11: C | E11: Transferência Constitucional - FUNDEB
A12: 07/04/2025 | B12: BB-APLIC C.PRZ-APL.AUT | C12: 764797.82 | D12: D | E12: Aplicação Financeira
A13: 10/04/2025 | B13: ITR | C13: 310.55 | D13: C | E13: Transferência Constitucional - FUNDEB
A14: 10/04/2025 | B14: FPE/FPM | C14: 970831.98 | D14: C | E14: Transferência Constitucional - FUNDEB
A15: 10/04/2025 | B15: FPE/FPM | C15: 2256898.7 | D15: C | E15: Transferência Constitucional - FUNDEB
A16: 10/04/2025 | B16: FPE/FPM | C16: 26109923 | D16: C | E16: Transferência Constitucional - FUNDEB
A17: 10/04/2025 | B17: FPE/FPM | C17: 11421.52 | D17: C | E17: Transferência Constitucional - FUNDEB
A18: 10/04/2025 | B18: IPI/EXPORTACAO | C18: 25654.02 | D18: C | E18: IPI/EXPORTACAO - Cota Débito
A19: 10/04/2025 | B19: IPI/EXPORTACAO | C19: 14883.18 | D19: C | E19: Transferência Constitucional - FUNDEB
A20: 10/04/2025 | B20: COTA DAF-DEBITO | C20: 25654.02 | D20: D | E20: IPI/EXPORTACAO - Cota Débito
A21: 10/04/2025 | B21: BB-APLIC C.PRZ-APL.AUT | C21: 29364268 | D21: D | E21: Aplicação Financeira
... A38: 22/04/2025 | B38: BB-APLIC C.PRZ-APL.AUT | C38: 1377329.9 | D38: D | E38: Aplicação Financeira
A39: 23/04/2025 | B39: Pagto via Auto-Atend.BB | C39: 333.78 | D39: D | E39: GRU-GUIA RECOLHIM. UNIAO | F39: Regularizado em Maio
A40: 23/04/2025 | B40: Pagto via Auto-Atend.BB | C40: 333.78 | D40: D | E40: GRU-GUIA RECOLHIM. UNIAO | F40: Regularizado em Maio
A41: 23/04/2025 | B41: Resgate Automático | C41: 667.56 | D41: C | E41: Resgate Automático
A42: 28/04/2025 | B42: RECEBIMENTO DE ICMS | C42: 12072894 | D42: C | E42: Transferência Constitucional - FUNDEB
A43: 28/04/2025 | B43: IPVA | C43: 411780.79 | D43: C | E43: Transferência Constitucional - FUNDEB
A44: 28/04/2025 | B44: BB-APLIC C.PRZ-APL.AUT | C44: 12484675 | D44: D | E44: Aplicação Financeira
A45: 29/04/2025 | B45: Folha de Pagamento | C45: 33884901 | D45: D | E45: Folha 04-2025
A46: 29/04/2025 | B46: Folha de Pagamento | C46: 574797.52 | D46: D | E46: Folha 04-2025
A47: 29/04/2025 | B47: Folha de Pagamento | C47: 271057.19 | D47: D | E47: Folha 04-2025
A48: 29/04/2025 | B48: Folha de Pagamento | C48: 694.48 | D48: D | E48: Folha 04-2025
A49: 29/04/2025 | B49: Folha de Pagamento | C49: 15343.9 | D49: D | E49: Folha 04-2025
A50: 29/04/2025 | B50: Folha de Pagamento | C50: 568544.14 | D50: D | E50: Folha 04-2025
A51: 29/04/2025 | B51: Pagamentos Diversos | C51: 17012.03 | D51: D | E51: Folha 04-2025
A52: 29/04/2025 | B52: Emissão Ordem Bancária | C52: 331945.21 | D52: D | E52: Folha 04-2025 | F52: 2025RE00358
A53: 29/04/2025 | B53: Resgate Automático | C53: 35664296 | D53: C | E53: Resgate Automático
A54: 30/04/2025 | B54: ITCMD | C54: 7240.43 | D54: C | E54: Transferência Constitucional - FUNDEB
A55: 30/04/2025 | B55: IPVA | C55: 768010.78 | D55: C | E55: Transferência Constitucional - FUNDEB
A56: 30/04/2025 | B56: ITR | C56: 46.66 | D56: C | E56: Transferência Constitucional - FUNDEB
...

Sheet Saldos - 04-2025
B2: CONCILIAÇÃO BANCÁRIA DO EXTRATO BANCÁRIO - ABRIL DE 2025
B4: 1. Ingressos | E4: Valores do Mês | F4: Acumulado
B5: 1.0 IPI - EXP | E5: 68716.47 | F5: =E5+'Saldos - 03-2025'!F5 -> 268481.33
B6: 1.1 VAAR | E6: 170738.33 | F6: =E6+'Saldos - 03-2025'!F6 -> 1648620.1
B7: 1.2 FPE/FPM | E7: 65917840 | F7: =E7+'Saldos - 03-2025'!F7 -> 3.0214171e+08
B8: 1.3 ICMS | E8: 14044831 | F8: =E8+'Saldos - 03-2025'!F8 -> 58551739
B9: 1.4 IPVA | E9: 2031296.7 | F9: =E9+'Saldos - 03-2025'!F9 -> 8006682.1
B10: 1.5 ITCMD | E10: 7240.43 | F10: =E10+'Saldos - 03-2025'!F10 -> 132946.87
B11: 1.6 ITR | E11: 439.44 | F11: =E11+'Saldos - 03-2025'!F11 -> 3855.91
B12: 1.7 ORDEM BANC CANCELADA | E12: 103.93 | F12: =E12+'Saldos - 03-2025'!F12 -> 326.29
B13: 1.8 RESGATE | E13: 75423795 | F13: =E13+'Saldos - 03-2025'!F13 -> 2.5117927e+08
B14: 2 Total das Entradas | E14: =SUM(E5:E13) -> 1.57665e+08 | F14: =SUM(F5:F13) -> 6.2193363e+08 | G14: ok
B15: 3.0 (-) IPI/Cota DAF Deb | E15: -43487.32 | F15: =E15+'Saldos - 03-2025'!F15 -> -169908.79
B16: 3.1 (-) Ordem Bancária Cancelada | E16: =-E12 -> -103.93 | F16: =E16+'Saldos - 03-2025'!F16 -> -326.29
B17: 3.2 (-) Resgastes efetuados | E17: =-E13 -> -75423795 | F17: =E17+'Saldos - 03-2025'!F17 -> -2.5117927e+08
B18: 3.3 (-) Ajuste VAAR - FNDE | E18: 0 | F18: =E18+'Saldos - 03-2025'!F18 -> -164645.69
B19: 3. Total Disponibizado( 1 - 3.0- 3.1 - 3.2 -3.3 - 3.4 ) | E19: =SUM(E14:E18) -> 82197615 | F19: =SUM(F14:F18) -> 3.7041948e+08 | G19: ok
B21: 4. Saídas | E21: Valores do Mês | F21: Acumulado
B22: 4.1 Cota DAF Deb | E22: 43487.32 | F22: =E22+'Saldos - 03-2025'!F22 -> 169908.79
B23: 4.2 O.B.s Canceladas | E23: 0 | F23: ='Saldos - 03-2025'!F23 -> 0
B24: 4.3.1 Folha de Pagamento - Encargos e Identificados por RE | E24: 40001146 | F24: =E24+'Saldos - 03-2025'!F24 -> 1.2186437e+08
B25: 4.3.2 Folha de Pagamento - Folha 01/2025 | E25: 0 | F25: =E25+'Saldos - 03-2025'!F25 -> 34311367
B26: 4.3.3 Folha de Pagamento - Folha 02/2025 | E26: 0 | F26: =E26+'Saldos - 03-2025'!F26 -> 34175582
B27: 4.3.4 Folha de Pagamento - Folha 03/2025 | E27: 0 | F27: =E27+'Saldos - 03-2025'!F27 -> 33980888
B28: 4.3.5 Folha de Pagamento - Folha 04/2025 | E28: 35798382 | F28: =E28 -> 35798382
B29: 4.3.6 Folha de Pagamento - Férias | E29: 0 | F29: =E29+'Saldos - 03-2025'!F28 -> 15697876
B30: 4.3.7 Ajuste VAAR | E30: 0 | F30: =E30+'Saldos - 03-2025'!F29 -> 164645.69
B31: 4.3.8 GRU-GUIA RECOLHIM. UNIAO | E31: 667.56 | F31: =E31+'Saldos - 03-2025'!F30 -> 3671.58
B32: 4.3.9 Pagamentos Diversos - Folha | E32: 0 | F32: =E32+'Saldos - 03-2025'!F31 -> 20059.12
B33: 4.4 Tarifa bancária | E33: 0 | F33: =E33+'Saldos - 03-2025'!F32 -> 7490.51
B34: 4.5 (-) Aplicações Efetuadas | E34: 81821318 | F34: =E34+'Saldos - 03-2025'!F33 -> 3.4573939e+08 | H34: ='Extrato 04-2025'!C2+'Extrato 03-2025'!C2+'Extrato 02-2025'!C2+'Extrato 01-2025'!C2-F35 -> 0
B35: 5. Total Geral das Saídas | E35: =SUM(E22:E34) -> 1.57665e+08 | F35: =SUM(F22:F34) -> 6.2193363e+08 | G35: ok | H35: =E35-E14 -> 0
B36: 6.1 (-) Cota DAF Deb | E36: =-E22 -> -43487.32 | F36: =E36+'Saldos - 03-2025'!F35 -> -169908.79
B37: 6.2 (-) Aplicações Efetuadas | E37: =-E34 -> -81821318 | F37: =E37+'Saldos - 03-2025'!F36 -> -3.4573939e+08
B38: 6.3 (-) O.B.s Canceladas | E38: -103.93 | F38: =E38+'Saldos - 03-2025'!F37 -> -215.11
B39: 6.4 (-) Tarifa bancária | E39: =-E33 -> 0 | F39: =E39+'Saldos - 03-2025'!F38 -> -7490.51
B40: 6.5 (-) Pagamento Folha não regularizado | E40: -48866.78 | F40: =E40+'Saldos - 03-2025'!F39 -> -34224449
B41: 6.6 (-) Ajustes VAAR | F41: =E41+'Saldos - 03-2025'!F40 -> -164645.69
B42: 6.7 (-) Pagamentos Diversos | F42: =E42+'Saldos - 03-2025'!F41 -> -20059.12
B43: 6.7 (+) Regularização de Folha e não Pago | F43: =E43+'Saldos - 03-2025'!F42 -> 34223471
...

Sheet Cálculo Conciliação 2º Bimestre
C3: Saldo dos Pagamentos do SEAFI | D3: 1.4604409e+08 | E3: 11470.64
C5: Extrato de Janeiro | D5: 58285284
C6: SEAFI a maior | D6: 8949.47 | G6: 58294233
C7: Extrato de Fevereiro | D7: 88938686
C8: SEAFI a menor ( regularizado em março ) | D8: -1194723.6 | E8: pago em março
C9: SEAFI a maior | D9: 5894.85 | G9: 87749857
C11: COMPOSIÇÃO DE SALDO DO FUNDEB
C12: 2º BIMESTRE DE 2025
C14: Dsiponibilidade Financeira em 31/12/2024 | D14: 15778860
C15: ( + ) Ingressos = Transferências Constitucionais - janeiro-2024 | D15: 92936040
C16: ( + ) Ingressos = Transferências Constitucionais - fevereiro-2024 | D16: 1.115289e+08 | I16: 2.0446494e+08
C17: ( + ) Ingressos = Transferências Constitucionais - Março-2024 | D17: 83756928
C18: ( + ) Ingressos = Transferências Constitucionais - Abril-2024 | D18: 82197615 | I18: 3.7041948e+08
C19: ( + ) Ingressos = Rendimentos do FUNDEB - 1º Bimestre | D19: 901662.73 | I19: 2.053666e+08
C20: ( + ) Ingressos = Rendimentos do FUNDEB - 2º Bimestre | D20: 1438396.9
C21: ( - ) Pagamentos Efetuados = Relatório de Execução Financeira | D21: -2.7583028e+08
C22: ( - ) Pagto Tarifa Bancária não regularizada no SEAFI | D22: -7490.51
C23: ( - ) Pagto de Folha - não regularizado | D23: -1533.94 | I23: -29083.57
C24: ( - ) Pagamentos Diversos - Folha | D24: -20059.12
C28: ( = ) Saldo do SIOPE | D28: 1.1267904e+08 | I28: 0.0099999905
C30: Dsiponibilidade Financeira em 28/02/2025 | D30: 1.1267904e+08
C32: Diferença a identificar | D32: 0.0099999905

Sheet Extrato 05-2025
A1: Extrato Conta Corrente
A2: Agencia | C2: =SUBTOTAL(9,C4:C66) -> 1.7919817e+08
A3: Data | B3: Historico | C3: Valor R$ | D3: Inf. | E3: Histórico | F3: Detalhamentos
A4: 05/05/2025 | B4: ITCMD | C4: 1600.4 | D4: C | E4: Transferência Constitucional - FUNDEB
A5: 05/05/2025 | B5: IPVA | C5: 168934.79 | D5: C | E5: Transferência Constitucional - FUNDEB
A6: 05/05/2025 | B6: RECEBIMENTO DE ICMS | C6: 1538804.2 | D6: C | E6: Transferência Constitucional - FUNDEB
A7: 05/05/2025 | B7: BB-APLIC C.PRZ-APL.AUT | C7: 1709339.4 | D7: D | E7: Aplicação Financeira
A8: 08/05/2025 | B8: ORDEM BANC CANCELADA | C8: 103.93 | D8: C | E8: ORDEM BANC CANCELADA | F8: 2025GD00955
A9: 08/05/2025 | B9: Emissão Ordem Bancária | C9: 35161499 | D9: D | E9: Folha de Pagamento | F9: 2025RE00370
A10: 08/05/2025 | B10: Emissão Ordem Bancária | C10: 6964816.8 | D10: D | E10: Folha de Pagamento | F10: 2025RE00371
A11: 08/05/2025 | B11: Resgate Automático | C11: 42126212 | D11: C | E11: Resgate Automático
A12: 09/05/2025 | B12: ITCMD | C12: 46.36 | D12: C | E12: Transferência Constitucional - FUNDEB
A13: 09/05/2025 | B13: ITCMD | C13: 6234.01 | D13: C | E13: Transferência Constitucional - FUNDEB
A14: 09/05/2025 | B14: IPVA | C14: 58776.57 | D14: C | E14: Transferência Constitucional - FUNDEB
A15: 09/05/2025 | B15: IPVA | C15: 137612.58 | D15: C | E15: Transferência Constitucional - FUNDEB
A16: 09/05/2025 | B16: ITR | C16: 1640.13 | D16: C | E16: Transferência Constitucional - FUNDEB
A17: 09/05/2025 | B17: RECEBIMENTO DE ICMS | C17: 32178.6 | D17: C | E17: Transferência Constitucional - FUNDEB
A18: 09/05/2025 | B18: RECEBIMENTO DE ICMS | C18: 580965.71 | D18: C | E18: Transferência Constitucional - FUNDEB
A19: 09/05/2025 | B19: FPE/FPM | C19: 1492064.2 | D19: C | E19: Transferência Constitucional - FUNDEB
A20: 09/05/2025 | B20: FPE/FPM | C20: 3468610.4 | D20: C | E20: Transferência Constitucional - FUNDEB
A21: 09/05/2025 | B21: FPE/FPM | C21: 40065193 | D21: C | E21: Transferência Constitucional - FUNDEB
A22: 09/05/2025 | B22: FPE/FPM | C22: 17553.67 | D22: C | E22: Transferência Constitucional - FUNDEB
... A30: 16/05/2025 | B30: BB-APLIC C.PRZ-APL.AUT | C30: 5871461 | D30: D | E30: Aplicação Financeira
A31: 19/05/2025 | B31: Emissão Ordem Bancária | C31: 70643.92 | D31: D | E31: Folha de Pagamento | F31: 2025RE00396
A32: 19/05/2025 | B32: Resgate Automático | C32: 70643.92 | D32: C | E32: Resgate Automático
A33: 20/05/2025 | B33: ITR | C33: 106.39 | D33: C | E33: Transferência Constitucional - FUNDEB
A34: 20/05/2025 | B34: FPE/FPM | C34: 325682.9 | D34: C | E34: Transferência Constitucional - FUNDEB
A35: 20/05/2025 | B35: FPE/FPM | C35: 757116.99 | D35: C | E35: Transferência Constitucional - FUNDEB
A36: 20/05/2025 | B36: FPE/FPM | C36: 8321549.5 | D36: C | E36: Transferência Constitucional - FUNDEB
A37: 20/05/2025 | B37: FPE/FPM | C37: 3831.54 | D37: C | E37: Transferência Constitucional - FUNDEB
A38: 20/05/2025 | B38: IPI/EXPORTACAO | C38: 8636.3 | D38: C | E38: IPI/EXPORTACAO - Cota Débito
A39: 20/05/2025 | B39: IPI/EXPORTACAO | C39: 5010.36 | D39: C | E39: Transferência Constitucional - FUNDEB
A40: 20/05/2025 | B40: COTA DAF-DEBITO | C40: 8636.3 | D40: D | E40: IPI/EXPORTACAO - Cota Débito
A41: 20/05/2025 | B41: BB-APLIC C.PRZ-APL.AUT | C41: 9413297.7 | D41: D | E41: Aplicação Financeira
A42: 23/05/2025 | B42: ITCMD | C42: 15845.21 | D42: C | E42: Transferência Constitucional - FUNDEB
A43: 23/05/2025 | B43: IPVA | C43: 384474.34 | D43: C | E43: Transferência Constitucional - FUNDEB
... A48: 29/05/2025 | B48: RECEBIMENTO DE ICMS | C48: 2714578.6 | D48: C | E48: Transferência Constitucional - FUNDEB
A49: 29/05/2025 | B49: Folha de Pagamento | C49: 33983595 | D49: D | E49: Folha 05/2025 | F49: Regularizado em Junho
A50: 29/05/2025 | B50: Folha de Pagamento | C50: 570670.66 | D50: D | E50: Folha 05/2025 | F50: Regularizado em Junho
A51: 29/05/2025 | B51: Folha de Pagamento | C51: 259507.21 | D51: D | E51: Folha 05/2025 | F51: Regularizado em Junho
...

Sheet Saldos - 05-2025
B2: CONCILIAÇÃO BANCÁRIA DO EXTRATO BANCÁRIO - MAIO DE 2025
B4: 1. Ingressos | E4: Valores do Mês | F4: Acumulado
B5: 1.0 IPI - EXP | E5: 66759.43 | F5: =E5+'Saldos - 04-2025'!F5 -> 335240.76
B6: 1.1 VAAR | E6: 0 | F6: =E6+'Saldos - 04-2025'!F6 -> 1648620.1
B7: 1.2 FPE/FPM | E7: 83831710 | F7: =E7+'Saldos - 04-2025'!F7 -> 3.8597342e+08
B8: 1.3 ICMS | E8: 19018969 | F8: =E8+'Saldos - 04-2025'!F8 -> 77570708
B9: 1.4 IPVA | E9: 1203990.6 | F9: =E9+'Saldos - 04-2025'!F9 -> 9210672.8
B10: 1.5 ITCMD | E10: 28418.13 | F10: =E10+'Saldos - 04-2025'!F10 -> 161365
B11: 1.6 ITR | E11: 1790.36 | F11: =E11+'Saldos - 04-2025'!F11 -> 5646.27
